<?xml version="1.0" encoding="UTF-8"?>
<!-- Generated by org.testng.reporters.JUnitXMLReporter -->
<testsuite ignored="0" hostname="LAPTOP-0HSGMNA0" failures="3" tests="29" name="Default test" time="143.551" errors="0" timestamp="2021-03-24T14:09:02 IST">
  <testcase classname="automation.testing.AutomatedTests" name="TC_01" time="2.821"/>
  <testcase classname="automation.testing.AutomatedTests" name="TC_02" time="3.475"/>
  <testcase classname="automation.testing.AutomatedTests" name="TC_03" time="4.054"/>
  <testcase classname="automation.testing.AutomatedTests" name="TC_04" time="3.016"/>
  <testcase classname="automation.testing.AutomatedTests" name="TC_05" time="5.07"/>
  <testcase classname="automation.testing.AutomatedTests" name="TC_06" time="5.52"/>
  <testcase classname="automation.testing.AutomatedTests" name="TC_07" time="3.792"/>
  <testcase classname="automation.testing.AutomatedTests" name="TC_08" time="3.589"/>
  <testcase classname="automation.testing.AutomatedTests" name="TC_09" time="4.211"/>
  <testcase classname="automation.testing.AutomatedTests" name="TC_10" time="3.662"/>
  <testcase classname="automation.testing.AutomatedTests" name="TC_11" time="2.254"/>
  <testcase classname="automation.testing.AutomatedTests" name="TC_12" time="1.549"/>
  <testcase classname="automation.testing.AutomatedTests" name="TC_13" time="3.174"/>
  <testcase classname="automation.testing.AutomatedTests" name="TC_14" time="3.462"/>
  <testcase classname="automation.testing.AutomatedTests" name="TC_15" time="5.743"/>
  <testcase classname="automation.testing.AutomatedTests" name="TC_16" time="9.7"/>
  <testcase classname="automation.testing.AutomatedTests" name="TC_17" time="4.522"/>
  <testcase classname="automation.testing.AutomatedTests" name="TC_18" time="9.198"/>
  <testcase classname="automation.testing.AutomatedTests" name="TC_19" time="9.274"/>
  <testcase classname="automation.testing.AutomatedTests" name="TC_20" time="5.365"/>
  <testcase classname="automation.testing.AutomatedTests" name="TC_21" time="5.578"/>
  <testcase classname="automation.testing.AutomatedTests" name="TC_22" time="5.367"/>
  <testcase classname="automation.testing.AutomatedTests" name="TC_23" time="5.376"/>
  <testcase classname="automation.testing.AutomatedTests" name="TC_24" time="5.033"/>
  <testcase classname="automation.testing.AutomatedTests" name="TC_25" time="6.134">
    <failure type="java.lang.AssertionError" message="The following asserts failed:
	The user didn&amp;apos;t get any error message for filling invalid &amp;quot;Recipient&amp;apos;s Email&amp;quot; expected [true] but found [false]">
      <![CDATA[java.lang.AssertionError: The following asserts failed:
The user didn't get any error message for filling invalid "Recipient's Email" expected [true] but found [false]
at org.testng.asserts.SoftAssert.assertAll(SoftAssert.java:47)
at org.testng.asserts.SoftAssert.assertAll(SoftAssert.java:31)
at automation.testing.TestScripts.tc_25_InvalidRecipientEmail(TestScripts.java:811)
at automation.testing.AutomatedTests.TC_25(AutomatedTests.java:164)
at java.base/jdk.internal.reflect.NativeMethodAccessorImpl.invoke0(Native Method)
at java.base/jdk.internal.reflect.NativeMethodAccessorImpl.invoke(NativeMethodAccessorImpl.java:62)
at java.base/jdk.internal.reflect.DelegatingMethodAccessorImpl.invoke(DelegatingMethodAccessorImpl.java:43)
at java.base/java.lang.reflect.Method.invoke(Method.java:566)
at org.testng.internal.MethodInvocationHelper.invokeMethod(MethodInvocationHelper.java:132)
at org.testng.internal.TestInvoker.invokeMethod(TestInvoker.java:599)
at org.testng.internal.TestInvoker.invokeTestMethod(TestInvoker.java:174)
at org.testng.internal.MethodRunner.runInSequence(MethodRunner.java:46)
at org.testng.internal.TestInvoker$MethodInvocationAgent.invoke(TestInvoker.java:822)
at org.testng.internal.TestInvoker.invokeTestMethods(TestInvoker.java:147)
at org.testng.internal.TestMethodWorker.invokeTestMethods(TestMethodWorker.java:146)
at org.testng.internal.TestMethodWorker.run(TestMethodWorker.java:128)
at java.base/java.util.ArrayList.forEach(ArrayList.java:1541)
at org.testng.TestRunner.privateRun(TestRunner.java:764)
at org.testng.TestRunner.run(TestRunner.java:585)
at org.testng.SuiteRunner.runTest(SuiteRunner.java:384)
at org.testng.SuiteRunner.runSequentially(SuiteRunner.java:378)
at org.testng.SuiteRunner.privateRun(SuiteRunner.java:337)
at org.testng.SuiteRunner.run(SuiteRunner.java:286)
at org.testng.SuiteRunnerWorker.runSuite(SuiteRunnerWorker.java:53)
at org.testng.SuiteRunnerWorker.run(SuiteRunnerWorker.java:96)
at org.testng.TestNG.runSuitesSequentially(TestNG.java:1218)
at org.testng.TestNG.runSuitesLocally(TestNG.java:1140)
at org.testng.TestNG.runSuites(TestNG.java:1069)
at org.testng.TestNG.run(TestNG.java:1037)
at org.testng.remote.AbstractRemoteTestNG.run(AbstractRemoteTestNG.java:115)
at org.testng.remote.RemoteTestNG.initAndRun(RemoteTestNG.java:251)
at org.testng.remote.RemoteTestNG.main(RemoteTestNG.java:77)
]]>
    </failure>
  </testcase> <!-- TC_25 -->
  <testcase classname="automation.testing.AutomatedTests" name="TC_26" time="5.319"/>
  <testcase classname="automation.testing.AutomatedTests" name="TC_27" time="5.958"/>
  <testcase classname="automation.testing.AutomatedTests" name="TC_28" time="5.214">
    <failure type="java.lang.AssertionError" message="The following asserts failed:
	The user didn&amp;apos;t get any error message for filling invalid &amp;quot;Recipient&amp;apos;s Name&amp;quot; expected [true] but found [false]">
      <![CDATA[java.lang.AssertionError: The following asserts failed:
The user didn't get any error message for filling invalid "Recipient's Name" expected [true] but found [false]
at org.testng.asserts.SoftAssert.assertAll(SoftAssert.java:47)
at org.testng.asserts.SoftAssert.assertAll(SoftAssert.java:31)
at automation.testing.TestScripts.tc_28_InvalidRecipientName(TestScripts.java:975)
at automation.testing.AutomatedTests.TC_28(AutomatedTests.java:179)
at java.base/jdk.internal.reflect.NativeMethodAccessorImpl.invoke0(Native Method)
at java.base/jdk.internal.reflect.NativeMethodAccessorImpl.invoke(NativeMethodAccessorImpl.java:62)
at java.base/jdk.internal.reflect.DelegatingMethodAccessorImpl.invoke(DelegatingMethodAccessorImpl.java:43)
at java.base/java.lang.reflect.Method.invoke(Method.java:566)
at org.testng.internal.MethodInvocationHelper.invokeMethod(MethodInvocationHelper.java:132)
at org.testng.internal.TestInvoker.invokeMethod(TestInvoker.java:599)
at org.testng.internal.TestInvoker.invokeTestMethod(TestInvoker.java:174)
at org.testng.internal.MethodRunner.runInSequence(MethodRunner.java:46)
at org.testng.internal.TestInvoker$MethodInvocationAgent.invoke(TestInvoker.java:822)
at org.testng.internal.TestInvoker.invokeTestMethods(TestInvoker.java:147)
at org.testng.internal.TestMethodWorker.invokeTestMethods(TestMethodWorker.java:146)
at org.testng.internal.TestMethodWorker.run(TestMethodWorker.java:128)
at java.base/java.util.ArrayList.forEach(ArrayList.java:1541)
at org.testng.TestRunner.privateRun(TestRunner.java:764)
at org.testng.TestRunner.run(TestRunner.java:585)
at org.testng.SuiteRunner.runTest(SuiteRunner.java:384)
at org.testng.SuiteRunner.runSequentially(SuiteRunner.java:378)
at org.testng.SuiteRunner.privateRun(SuiteRunner.java:337)
at org.testng.SuiteRunner.run(SuiteRunner.java:286)
at org.testng.SuiteRunnerWorker.runSuite(SuiteRunnerWorker.java:53)
at org.testng.SuiteRunnerWorker.run(SuiteRunnerWorker.java:96)
at org.testng.TestNG.runSuitesSequentially(TestNG.java:1218)
at org.testng.TestNG.runSuitesLocally(TestNG.java:1140)
at org.testng.TestNG.runSuites(TestNG.java:1069)
at org.testng.TestNG.run(TestNG.java:1037)
at org.testng.remote.AbstractRemoteTestNG.run(AbstractRemoteTestNG.java:115)
at org.testng.remote.RemoteTestNG.initAndRun(RemoteTestNG.java:251)
at org.testng.remote.RemoteTestNG.main(RemoteTestNG.java:77)
]]>
    </failure>
  </testcase> <!-- TC_28 -->
  <testcase classname="automation.testing.AutomatedTests" name="TC_29" time="5.967">
    <failure type="java.lang.AssertionError" message="The following asserts failed:
	The user didn&amp;apos;t get any error message for filling invalid &amp;quot;Your Name&amp;quot; expected [true] but found [false]">
      <![CDATA[java.lang.AssertionError: The following asserts failed:
The user didn't get any error message for filling invalid "Your Name" expected [true] but found [false]
at org.testng.asserts.SoftAssert.assertAll(SoftAssert.java:47)
at org.testng.asserts.SoftAssert.assertAll(SoftAssert.java:31)
at automation.testing.TestScripts.tc_29_InvalidYourName(TestScripts.java:1030)
at automation.testing.AutomatedTests.TC_29(AutomatedTests.java:184)
at java.base/jdk.internal.reflect.NativeMethodAccessorImpl.invoke0(Native Method)
at java.base/jdk.internal.reflect.NativeMethodAccessorImpl.invoke(NativeMethodAccessorImpl.java:62)
at java.base/jdk.internal.reflect.DelegatingMethodAccessorImpl.invoke(DelegatingMethodAccessorImpl.java:43)
at java.base/java.lang.reflect.Method.invoke(Method.java:566)
at org.testng.internal.MethodInvocationHelper.invokeMethod(MethodInvocationHelper.java:132)
at org.testng.internal.TestInvoker.invokeMethod(TestInvoker.java:599)
at org.testng.internal.TestInvoker.invokeTestMethod(TestInvoker.java:174)
at org.testng.internal.MethodRunner.runInSequence(MethodRunner.java:46)
at org.testng.internal.TestInvoker$MethodInvocationAgent.invoke(TestInvoker.java:822)
at org.testng.internal.TestInvoker.invokeTestMethods(TestInvoker.java:147)
at org.testng.internal.TestMethodWorker.invokeTestMethods(TestMethodWorker.java:146)
at org.testng.internal.TestMethodWorker.run(TestMethodWorker.java:128)
at java.base/java.util.ArrayList.forEach(ArrayList.java:1541)
at org.testng.TestRunner.privateRun(TestRunner.java:764)
at org.testng.TestRunner.run(TestRunner.java:585)
at org.testng.SuiteRunner.runTest(SuiteRunner.java:384)
at org.testng.SuiteRunner.runSequentially(SuiteRunner.java:378)
at org.testng.SuiteRunner.privateRun(SuiteRunner.java:337)
at org.testng.SuiteRunner.run(SuiteRunner.java:286)
at org.testng.SuiteRunnerWorker.runSuite(SuiteRunnerWorker.java:53)
at org.testng.SuiteRunnerWorker.run(SuiteRunnerWorker.java:96)
at org.testng.TestNG.runSuitesSequentially(TestNG.java:1218)
at org.testng.TestNG.runSuitesLocally(TestNG.java:1140)
at org.testng.TestNG.runSuites(TestNG.java:1069)
at org.testng.TestNG.run(TestNG.java:1037)
at org.testng.remote.AbstractRemoteTestNG.run(AbstractRemoteTestNG.java:115)
at org.testng.remote.RemoteTestNG.initAndRun(RemoteTestNG.java:251)
at org.testng.remote.RemoteTestNG.main(RemoteTestNG.java:77)
]]>
    </failure>
  </testcase> <!-- TC_29 -->
</testsuite> <!-- Default test -->
